Traceback (most recent call last):
  File "/opt/hostedtoolcache/Python/3.11.12/x64/lib/python3.11/site-packages/jupyter_cache/executors/utils.py", line 58, in single_nb_execution
    executenb(
  File "/opt/hostedtoolcache/Python/3.11.12/x64/lib/python3.11/site-packages/nbclient/client.py", line 1319, in execute
    return NotebookClient(nb=nb, resources=resources, km=km, **kwargs).execute()
           ^^^^^^^^^^^^^^^^^^^^^^^^^^^^^^^^^^^^^^^^^^^^^^^^^^^^^^^^^^^^^^^^^^^^^
  File "/opt/hostedtoolcache/Python/3.11.12/x64/lib/python3.11/site-packages/jupyter_core/utils/__init__.py", line 165, in wrapped
    return loop.run_until_complete(inner)
           ^^^^^^^^^^^^^^^^^^^^^^^^^^^^^^
  File "/opt/hostedtoolcache/Python/3.11.12/x64/lib/python3.11/asyncio/base_events.py", line 654, in run_until_complete
    return future.result()
           ^^^^^^^^^^^^^^^
  File "/opt/hostedtoolcache/Python/3.11.12/x64/lib/python3.11/site-packages/nbclient/client.py", line 709, in async_execute
    await self.async_execute_cell(
  File "/opt/hostedtoolcache/Python/3.11.12/x64/lib/python3.11/site-packages/nbclient/client.py", line 1062, in async_execute_cell
    await self._check_raise_for_error(cell, cell_index, exec_reply)
  File "/opt/hostedtoolcache/Python/3.11.12/x64/lib/python3.11/site-packages/nbclient/client.py", line 918, in _check_raise_for_error
    raise CellExecutionError.from_cell_and_msg(cell, exec_reply_content)
nbclient.exceptions.CellExecutionError: An error occurred while executing the following cell:
------------------
plot_models([Lasso, Lasso, Lasso], polynomials=[True,True,False], alphas=(0, 1, 0), figsize=(10, 8), title="3 suggested models", legend=[ "training data","model 1", "model 2", "model 3"])

------------------


[0;31m---------------------------------------------------------------------------[0m
[0;31mTypeError[0m                                 Traceback (most recent call last)
Cell [0;32mIn[6], line 1[0m
[0;32m----> 1[0m [43mplot_models[49m[43m([49m[43m[[49m[43mLasso[49m[43m,[49m[43m [49m[43mLasso[49m[43m,[49m[43m [49m[43mLasso[49m[43m][49m[43m,[49m[43m [49m[43mpolynomials[49m[38;5;241;43m=[39;49m[43m[[49m[38;5;28;43;01mTrue[39;49;00m[43m,[49m[38;5;28;43;01mTrue[39;49;00m[43m,[49m[38;5;28;43;01mFalse[39;49;00m[43m][49m[43m,[49m[43m [49m[43malphas[49m[38;5;241;43m=[39;49m[43m([49m[38;5;241;43m0[39;49m[43m,[49m[43m [49m[38;5;241;43m1[39;49m[43m,[49m[43m [49m[38;5;241;43m0[39;49m[43m)[49m[43m,[49m[43m [49m[43mfigsize[49m[38;5;241;43m=[39;49m[43m([49m[38;5;241;43m10[39;49m[43m,[49m[43m [49m[38;5;241;43m8[39;49m[43m)[49m[43m,[49m[43m [49m[43mtitle[49m[38;5;241;43m=[39;49m[38;5;124;43m"[39;49m[38;5;124;43m3 suggested models[39;49m[38;5;124;43m"[39;49m[43m,[49m[43m [49m[43mlegend[49m[38;5;241;43m=[39;49m[43m[[49m[43m [49m[38;5;124;43m"[39;49m[38;5;124;43mtraining data[39;49m[38;5;124;43m"[39;49m[43m,[49m[38;5;124;43m"[39;49m[38;5;124;43mmodel 1[39;49m[38;5;124;43m"[39;49m[43m,[49m[43m [49m[38;5;124;43m"[39;49m[38;5;124;43mmodel 2[39;49m[38;5;124;43m"[39;49m[43m,[49m[43m [49m[38;5;124;43m"[39;49m[38;5;124;43mmodel 3[39;49m[38;5;124;43m"[39;49m[43m][49m[43m)[49m

[0;31mTypeError[0m: plot_models() got an unexpected keyword argument 'figsize'

